*** Starting uWSGI 2.0.18-debian (64bit) on [Wed Jan 24 15:00:31 2024] ***
compiled with version: 8.2.0 on 10 February 2019 02:42:46
os: Linux-5.4.0-aidlite #1 SMP PREEMPT Thu Apr 21 03:06:08 CST 2022
nodename: localhost
machine: aarch64
clock source: unix
pcre jit disabled
detected number of CPU cores: 8
current working directory: /var/www/web
writing pidfile to uwsgi.pid
detected binary path: /usr/bin/uwsgi-core
uWSGI running as root, you can use --uid/--gid/--chroot options
*** WARNING: you are running uWSGI as root !!! (use the --uid flag) *** 
chdir() to /var/www/web
your processes number limit is 13584
your memory page size is 4096 bytes
detected max file descriptor number: 32768
lock engine: pthread robust mutexes
thunder lock: disabled (you can enable it with --thunder-lock)
uwsgi socket 0 bound to TCP address 127.0.0.1:1080 fd 3
uWSGI running as root, you can use --uid/--gid/--chroot options
*** WARNING: you are running uWSGI as root !!! (use the --uid flag) *** 
Python version: 3.7.3 (default, Oct 11 2023, 09:51:27)  [GCC 8.3.0]
Python main interpreter initialized at 0x30001194c0
uWSGI running as root, you can use --uid/--gid/--chroot options
*** WARNING: you are running uWSGI as root !!! (use the --uid flag) *** 
python threads support enabled
your server socket listen backlog is limited to 100 connections
your mercy for graceful operations on workers is 60 seconds
mapped 281440 bytes (274 KB) for 2 cores
*** Operational MODE: threaded ***
added /usr/bin/python to pythonpath.
WSGI app 0 (mountpoint='') ready in 6 seconds on interpreter 0x30001194c0 pid: 8592 (default app)
uWSGI running as root, you can use --uid/--gid/--chroot options
*** WARNING: you are running uWSGI as root !!! (use the --uid flag) *** 
*** uWSGI is running in multiple interpreter mode ***
spawned uWSGI master process (pid: 8592)
spawned uWSGI worker 1 (pid: 8617, cores: 2)
*** Stats server enabled on 127.0.0.1:5000 fd: 13 ***
[pid: 8617|app: 0|req: 1/1] 127.0.0.1 () {34 vars in 684 bytes} [Wed Jan 24 15:00:44 2024] GET / => generated 146 bytes in 61 msecs (HTTP/1.0 200) 2 headers in 80 bytes (1 switches on core 0)
signal only works in main thread
open the cam:1 ...
[pid: 8617|app: 0|req: 3/2] 127.0.0.1 () {36 vars in 750 bytes} [Wed Jan 24 15:01:29 2024] GET / => generated 146 bytes in 4 msecs (HTTP/1.0 200) 2 headers in 80 bytes (1 switches on core 0)
('app runs on port:', 39676)
open the cam:1 ...
remi.server      INFO     Started httpserver http://0.0.0.0:39676/
remi.request     INFO     built UI (path=/)
remi.server.ws   INFO     connection established: ('127.0.0.1', 46624)
remi.server.ws   INFO     handshake complete
Wed Jan 24 15:01:30 2024 - SIGPIPE: writing to a closed pipe/socket/fd (probably the client disconnected) !!!
Wed Jan 24 15:01:30 2024 - SIGPIPE: writing to a closed pipe/socket/fd (probably the client disconnected) !!!
remi.server.ws   ERROR    Error managing incoming websocket message
Traceback (most recent call last):
  File "/usr/local/lib/python3.7/dist-packages/remi/server.py", line 175, in read_next_message
    self.on_message(from_websocket(decoded))
  File "/usr/local/lib/python3.7/dist-packages/remi/server.py", line 245, in on_message
    self.send_message(_MSG_ACK)
  File "/usr/local/lib/python3.7/dist-packages/remi/server.py", line 209, in send_message
    self.request.sendall(out)
BrokenPipeError: [Errno 32] Broken pipe
remi.request     ERROR    sending websocket spontaneous message
Traceback (most recent call last):
  File "/usr/local/lib/python3.7/dist-packages/remi/server.py", line 497, in _send_spontaneous_websocket_message
    if ws.send_message(message):
  File "/usr/local/lib/python3.7/dist-packages/remi/server.py", line 209, in send_message
    self.request.sendall(out)
BrokenPipeError: [Errno 32] Broken pipe
remi.server.ws   INFO     connection established: ('127.0.0.1', 46636)
remi.server.ws   INFO     handshake complete
Corrupt JPEG data: bad Huffman code
Corrupt JPEG data: bad Huffman code
Corrupt JPEG data: bad Huffman code
Wed Jan 24 15:04:24 2024 - SIGPIPE: writing to a closed pipe/socket/fd (probably the client disconnected) !!!
Wed Jan 24 15:04:24 2024 - uwsgi_response_write_body_do(): Broken pipe [core/writer.c line 429] during GET /video_feed (127.0.0.1)
OSError: write error
Exception ignored in: <function VideoCamera.__del__ at 0x7892435840>
Traceback (most recent call last):
  File "./camera.py", line 15, in __del__
    self.video.release()
AttributeError: 'cv3' object has no attribute 'release'
[pid: 8617|app: 0|req: 4/3] 127.0.0.1 () {34 vars in 673 bytes} [Wed Jan 24 15:01:29 2024] GET /video_feed => generated 63593254 bytes in 174946 msecs (HTTP/1.0 200) 1 headers in 76 bytes (1746 switches on core 0)
[pid: 8617|app: 0|req: 5/4] 127.0.0.1 () {34 vars in 882 bytes} [Wed Jan 24 15:04:24 2024] GET / => generated 146 bytes in 5 msecs (HTTP/1.0 200) 2 headers in 80 bytes (1 switches on core 0)
[pid: 8617|app: 0|req: 6/5] 127.0.0.1 () {34 vars in 882 bytes} [Wed Jan 24 15:04:24 2024] GET / => generated 146 bytes in 3 msecs (HTTP/1.0 200) 2 headers in 80 bytes (1 switches on core 0)
[pid: 8617|app: 0|req: 7/6] 127.0.0.1 () {34 vars in 882 bytes} [Wed Jan 24 15:04:24 2024] GET / => generated 146 bytes in 4 msecs (HTTP/1.0 200) 2 headers in 80 bytes (1 switches on core 0)
[pid: 8617|app: 0|req: 8/7] 127.0.0.1 () {32 vars in 674 bytes} [Wed Jan 24 15:04:24 2024] GET / => generated 146 bytes in 13 msecs (HTTP/1.0 200) 2 headers in 80 bytes (1 switches on core 0)
[pid: 8617|app: 0|req: 9/8] 127.0.0.1 () {32 vars in 722 bytes} [Wed Jan 24 15:04:24 2024] GET / => generated 146 bytes in 11 msecs (HTTP/1.0 200) 2 headers in 80 bytes (1 switches on core 0)
[pid: 8617|app: 0|req: 10/9] 127.0.0.1 () {32 vars in 697 bytes} [Wed Jan 24 15:04:24 2024] GET /favicon.ico => generated 232 bytes in 3 msecs (HTTP/1.0 404) 2 headers in 87 bytes (1 switches on core 0)
('app runs on port:', 39676)
open the cam:1 ...
Exception in thread Thread-3706:
Traceback (most recent call last):
  File "/usr/lib/python3.7/threading.py", line 917, in _bootstrap_inner
    self.run()
  File "/usr/lib/python3.7/threading.py", line 865, in run
    self._target(*self._args, **self._kwargs)
  File "cvs.py", line 184, in cvs.startcv
  File "/usr/local/lib/python3.7/dist-packages/remi/server.py", line 925, in start
    s = Server(main_gui_class, start=True, **kwargs)
  File "/usr/local/lib/python3.7/dist-packages/remi/server.py", line 816, in __init__
    self.start()
  File "/usr/local/lib/python3.7/dist-packages/remi/server.py", line 834, in start
    self, self._certfile, self._keyfile, self._ssl_version, *self._userdata)
  File "/usr/local/lib/python3.7/dist-packages/remi/server.py", line 762, in __init__
    HTTPServer.__init__(self, server_address, RequestHandlerClass)
  File "/usr/lib/python3.7/socketserver.py", line 452, in __init__
    self.server_bind()
  File "/usr/lib/python3.7/http/aid_server.py", line 138, in server_bind
    socketserver.TCPServer.server_bind(self)
  File "/usr/lib/python3.7/socketserver.py", line 466, in server_bind
    self.socket.bind(self.server_address)
OSError: [Errno 98] Address already in use

remi.server.ws   INFO     connection established: ('127.0.0.1', 54122)
remi.server.ws   INFO     handshake complete
Wed Jan 24 15:04:25 2024 - SIGPIPE: writing to a closed pipe/socket/fd (probably the client disconnected) !!!
remi.server.ws   ERROR    Error managing incoming websocket message
Traceback (most recent call last):
  File "/usr/local/lib/python3.7/dist-packages/remi/server.py", line 175, in read_next_message
    self.on_message(from_websocket(decoded))
  File "/usr/local/lib/python3.7/dist-packages/remi/server.py", line 245, in on_message
    self.send_message(_MSG_ACK)
  File "/usr/local/lib/python3.7/dist-packages/remi/server.py", line 209, in send_message
    self.request.sendall(out)
BrokenPipeError: [Errno 32] Broken pipe
remi.request     ERROR    sending websocket spontaneous message
Traceback (most recent call last):
  File "/usr/local/lib/python3.7/dist-packages/remi/server.py", line 497, in _send_spontaneous_websocket_message
    if ws.send_message(message):
  File "/usr/local/lib/python3.7/dist-packages/remi/server.py", line 209, in send_message
    self.request.sendall(out)
OSError: [Errno 9] Bad file descriptor
remi.server.ws   INFO     connection established: ('127.0.0.1', 54144)
remi.server.ws   INFO     handshake complete
Wed Jan 24 15:04:46 2024 - SIGPIPE: writing to a closed pipe/socket/fd (probably the client disconnected) !!!
Wed Jan 24 15:04:46 2024 - uwsgi_response_write_body_do(): Broken pipe [core/writer.c line 429] during GET /video_feed (127.0.0.1)
OSError: write error
Exception ignored in: <function VideoCamera.__del__ at 0x7892435840>
Traceback (most recent call last):
  File "./camera.py", line 15, in __del__
    self.video.release()
AttributeError: 'cv3' object has no attribute 'release'
[pid: 8617|app: 0|req: 11/10] 127.0.0.1 () {32 vars in 704 bytes} [Wed Jan 24 15:04:24 2024] GET /video_feed => generated 8575434 bytes in 21889 msecs (HTTP/1.0 200) 1 headers in 76 bytes (216 switches on core 0)
[pid: 8617|app: 0|req: 12/11] 127.0.0.1 () {32 vars in 706 bytes} [Wed Jan 24 15:04:46 2024] GET /favicon.ico => generated 232 bytes in 3 msecs (HTTP/1.0 404) 2 headers in 87 bytes (1 switches on core 0)
Corrupt JPEG data: bad Huffman code
[pid: 8617|app: 0|req: 13/12] 127.0.0.1 () {34 vars in 753 bytes} [Wed Jan 24 15:04:56 2024] GET / => generated 146 bytes in 4 msecs (HTTP/1.0 200) 2 headers in 80 bytes (1 switches on core 0)
('app runs on port:', 39676)
Exception in thread Thread-4614:
Traceback (most recent call last):
  File "/usr/lib/python3.7/threading.py", line 917, in _bootstrap_inner
    self.run()
  File "/usr/lib/python3.7/threading.py", line 865, in run
    self._target(*self._args, **self._kwargs)
  File "cvs.py", line 184, in cvs.startcv
  File "/usr/local/lib/python3.7/dist-packages/remi/server.py", line 925, in start
    s = Server(main_gui_class, start=True, **kwargs)
  File "/usr/local/lib/python3.7/dist-packages/remi/server.py", line 816, in __init__
    self.start()
  File "/usr/local/lib/python3.7/dist-packages/remi/server.py", line 834, in start
    self, self._certfile, self._keyfile, self._ssl_version, *self._userdata)
  File "/usr/local/lib/python3.7/dist-packages/remi/server.py", line 762, in __init__
    HTTPServer.__init__(self, server_address, RequestHandlerClass)
  File "/usr/lib/python3.7/socketserver.py", line 452, in __init__
    self.server_bind()
  File "/usr/lib/python3.7/http/aid_server.py", line 138, in server_bind
    socketserver.TCPServer.server_bind(self)
  File "/usr/lib/python3.7/socketserver.py", line 466, in server_bind
    self.socket.bind(self.server_address)
OSError: [Errno 98] Address already in use

open the cam:1 ...
remi.server.ws   INFO     connection established: ('127.0.0.1', 55952)
remi.server.ws   INFO     handshake complete
Wed Jan 24 15:04:58 2024 - SIGPIPE: writing to a closed pipe/socket/fd (probably the client disconnected) !!!
Wed Jan 24 15:04:58 2024 - SIGPIPE: writing to a closed pipe/socket/fd (probably the client disconnected) !!!
remi.server.ws   ERROR    Error managing incoming websocket message
Traceback (most recent call last):
  File "/usr/local/lib/python3.7/dist-packages/remi/server.py", line 175, in read_next_message
    self.on_message(from_websocket(decoded))
  File "/usr/local/lib/python3.7/dist-packages/remi/server.py", line 245, in on_message
    self.send_message(_MSG_ACK)
  File "/usr/local/lib/python3.7/dist-packages/remi/server.py", line 209, in send_message
    self.request.sendall(out)
BrokenPipeError: [Errno 32] Broken pipe
remi.request     ERROR    sending websocket spontaneous message
Traceback (most recent call last):
  File "/usr/local/lib/python3.7/dist-packages/remi/server.py", line 497, in _send_spontaneous_websocket_message
    if ws.send_message(message):
  File "/usr/local/lib/python3.7/dist-packages/remi/server.py", line 209, in send_message
    self.request.sendall(out)
BrokenPipeError: [Errno 32] Broken pipe
remi.server.ws   INFO     connection established: ('127.0.0.1', 55974)
remi.server.ws   INFO     handshake complete
Corrupt JPEG data: bad Huffman code
Corrupt JPEG data: bad Huffman code
Corrupt JPEG data: bad Huffman code
Wed Jan 24 15:05:27 2024 - SIGPIPE: writing to a closed pipe/socket/fd (probably the client disconnected) !!!
Wed Jan 24 15:05:27 2024 - uwsgi_response_write_body_do(): Broken pipe [core/writer.c line 429] during GET /video_feed (127.0.0.1)
OSError: write error
Exception ignored in: <function VideoCamera.__del__ at 0x7892435840>
Traceback (most recent call last):
  File "./camera.py", line 15, in __del__
    self.video.release()
AttributeError: 'cv3' object has no attribute 'release'
[pid: 8617|app: 0|req: 14/13] 127.0.0.1 () {32 vars in 704 bytes} [Wed Jan 24 15:04:56 2024] GET /video_feed => generated 11889666 bytes in 30709 msecs (HTTP/1.0 200) 1 headers in 76 bytes (300 switches on core 0)
[pid: 8617|app: 0|req: 15/14] 127.0.0.1 () {32 vars in 706 bytes} [Wed Jan 24 15:05:27 2024] GET /favicon.ico => generated 232 bytes in 2 msecs (HTTP/1.0 404) 2 headers in 87 bytes (1 switches on core 0)
Corrupt JPEG data: bad Huffman code
Corrupt JPEG data: bad Huffman code
[pid: 8617|app: 0|req: 16/15] 127.0.0.1 () {42 vars in 735 bytes} [Wed Jan 24 15:06:06 2024] GET / => generated 146 bytes in 6 msecs (HTTP/1.0 200) 2 headers in 80 bytes (1 switches on core 0)
('app runs on port:', 39676)
Exception in thread Thread-5934:
Traceback (most recent call last):
  File "/usr/lib/python3.7/threading.py", line 917, in _bootstrap_inner
    self.run()
  File "/usr/lib/python3.7/threading.py", line 865, in run
    self._target(*self._args, **self._kwargs)
  File "cvs.py", line 184, in cvs.startcv
  File "/usr/local/lib/python3.7/dist-packages/remi/server.py", line 925, in start
    s = Server(main_gui_class, start=True, **kwargs)
  File "/usr/local/lib/python3.7/dist-packages/remi/server.py", line 816, in __init__
    self.start()
  File "/usr/local/lib/python3.7/dist-packages/remi/server.py", line 834, in start
    self, self._certfile, self._keyfile, self._ssl_version, *self._userdata)
  File "/usr/local/lib/python3.7/dist-packages/remi/server.py", line 762, in __init__
    HTTPServer.__init__(self, server_address, RequestHandlerClass)
  File "/usr/lib/python3.7/socketserver.py", line 452, in __init__
    self.server_bind()
  File "/usr/lib/python3.7/http/aid_server.py", line 138, in server_bind
    socketserver.TCPServer.server_bind(self)
  File "/usr/lib/python3.7/socketserver.py", line 466, in server_bind
    self.socket.bind(self.server_address)
OSError: [Errno 98] Address already in use

open the cam:1 ...
remi.server.ws   INFO     connection established: ('127.0.0.1', 58590)
remi.server.ws   INFO     handshake complete
remi.server.ws   ERROR    Error managing incoming websocket message
Traceback (most recent call last):
  File "/usr/local/lib/python3.7/dist-packages/remi/server.py", line 175, in read_next_message
    self.on_message(from_websocket(decoded))
  File "/usr/local/lib/python3.7/dist-packages/remi/server.py", line 245, in on_message
    self.send_message(_MSG_ACK)
  File "/usr/local/lib/python3.7/dist-packages/remi/server.py", line 209, in send_message
    self.request.sendall(out)
ConnectionResetError: [Errno 104] Connection reset by peer
remi.request     ERROR    sending websocket spontaneous message
Traceback (most recent call last):
  File "/usr/local/lib/python3.7/dist-packages/remi/server.py", line 497, in _send_spontaneous_websocket_message
    if ws.send_message(message):
  File "/usr/local/lib/python3.7/dist-packages/remi/server.py", line 209, in send_message
    self.request.sendall(out)
OSError: [Errno 9] Bad file descriptor
remi.server.ws   INFO     connection established: ('127.0.0.1', 58604)
remi.server.ws   INFO     handshake complete
Corrupt JPEG data: bad Huffman code
Wed Jan 24 15:06:25 2024 - SIGPIPE: writing to a closed pipe/socket/fd (probably the client disconnected) !!!
Wed Jan 24 15:06:25 2024 - uwsgi_response_write_body_do(): Broken pipe [core/writer.c line 429] during GET /video_feed (127.0.0.1)
OSError: write error
Exception ignored in: <function VideoCamera.__del__ at 0x7892435840>
Traceback (most recent call last):
  File "./camera.py", line 15, in __del__
    self.video.release()
AttributeError: 'cv3' object has no attribute 'release'
[pid: 8617|app: 0|req: 17/16] 127.0.0.1 () {48 vars in 1011 bytes} [Wed Jan 24 15:06:07 2024] GET /video_feed => generated 6476957 bytes in 18653 msecs (HTTP/1.0 200) 1 headers in 76 bytes (164 switches on core 0)
[pid: 8617|app: 0|req: 18/17] 127.0.0.1 () {42 vars in 735 bytes} [Wed Jan 24 15:06:28 2024] GET / => generated 146 bytes in 5 msecs (HTTP/1.0 200) 2 headers in 80 bytes (1 switches on core 0)
('app runs on port:', 39676)
open the cam:1 ...
Exception in thread Thread-6231:
Traceback (most recent call last):
  File "/usr/lib/python3.7/threading.py", line 917, in _bootstrap_inner
    self.run()
  File "/usr/lib/python3.7/threading.py", line 865, in run
    self._target(*self._args, **self._kwargs)
  File "cvs.py", line 184, in cvs.startcv
  File "/usr/local/lib/python3.7/dist-packages/remi/server.py", line 925, in start
    s = Server(main_gui_class, start=True, **kwargs)
  File "/usr/local/lib/python3.7/dist-packages/remi/server.py", line 816, in __init__
    self.start()
  File "/usr/local/lib/python3.7/dist-packages/remi/server.py", line 834, in start
    self, self._certfile, self._keyfile, self._ssl_version, *self._userdata)
  File "/usr/local/lib/python3.7/dist-packages/remi/server.py", line 762, in __init__
    HTTPServer.__init__(self, server_address, RequestHandlerClass)
  File "/usr/lib/python3.7/socketserver.py", line 452, in __init__
    self.server_bind()
  File "/usr/lib/python3.7/http/aid_server.py", line 138, in server_bind
    socketserver.TCPServer.server_bind(self)
  File "/usr/lib/python3.7/socketserver.py", line 466, in server_bind
    self.socket.bind(self.server_address)
OSError: [Errno 98] Address already in use

remi.server.ws   INFO     connection established: ('127.0.0.1', 59188)
remi.server.ws   INFO     handshake complete
Corrupt JPEG data: bad Huffman code
Wed Jan 24 15:06:53 2024 - SIGPIPE: writing to a closed pipe/socket/fd (probably the client disconnected) !!!
Wed Jan 24 15:06:53 2024 - uwsgi_response_write_body_do(): Broken pipe [core/writer.c line 429] during GET /video_feed (127.0.0.1)
OSError: write error
Exception ignored in: <function VideoCamera.__del__ at 0x7892435840>
Traceback (most recent call last):
  File "./camera.py", line 15, in __del__
    self.video.release()
AttributeError: 'cv3' object has no attribute 'release'
[pid: 8617|app: 0|req: 19/18] 127.0.0.1 () {48 vars in 1011 bytes} [Wed Jan 24 15:06:28 2024] GET /video_feed => generated 9000644 bytes in 24947 msecs (HTTP/1.0 200) 1 headers in 76 bytes (229 switches on core 0)
[pid: 8617|app: 0|req: 20/19] 127.0.0.1 () {48 vars in 894 bytes} [Wed Jan 24 15:06:53 2024] GET / => generated 146 bytes in 4 msecs (HTTP/1.0 200) 2 headers in 80 bytes (1 switches on core 0)
('app runs on port:', 39676)
Exception in thread Thread-6529:
Traceback (most recent call last):
  File "/usr/lib/python3.7/threading.py", line 917, in _bootstrap_inner
    self.run()
  File "/usr/lib/python3.7/threading.py", line 865, in run
    self._target(*self._args, **self._kwargs)
  File "cvs.py", line 184, in cvs.startcv
  File "/usr/local/lib/python3.7/dist-packages/remi/server.py", line 925, in start
    s = Server(main_gui_class, start=True, **kwargs)
  File "/usr/local/lib/python3.7/dist-packages/remi/server.py", line 816, in __init__
    self.start()
  File "/usr/local/lib/python3.7/dist-packages/remi/server.py", line 834, in start
    self, self._certfile, self._keyfile, self._ssl_version, *self._userdata)
  File "/usr/local/lib/python3.7/dist-packages/remi/server.py", line 762, in __init__
    HTTPServer.__init__(self, server_address, RequestHandlerClass)
  File "/usr/lib/python3.7/socketserver.py", line 452, in __init__
    self.server_bind()
  File "/usr/lib/python3.7/http/aid_server.py", line 138, in server_bind
    socketserver.TCPServer.server_bind(self)
  File "/usr/lib/python3.7/socketserver.py", line 466, in server_bind
    self.socket.bind(self.server_address)
OSError: [Errno 98] Address already in use

open the cam:1 ...
remi.server.ws   INFO     connection established: ('127.0.0.1', 59794)
remi.server.ws   INFO     handshake complete
Wed Jan 24 15:06:56 2024 - SIGPIPE: writing to a closed pipe/socket/fd (probably the client disconnected) !!!
remi.server.ws   ERROR    Error managing incoming websocket message
Traceback (most recent call last):
  File "/usr/local/lib/python3.7/dist-packages/remi/server.py", line 175, in read_next_message
    self.on_message(from_websocket(decoded))
  File "/usr/local/lib/python3.7/dist-packages/remi/server.py", line 245, in on_message
    self.send_message(_MSG_ACK)
  File "/usr/local/lib/python3.7/dist-packages/remi/server.py", line 209, in send_message
    self.request.sendall(out)
BrokenPipeError: [Errno 32] Broken pipe
remi.server.ws   INFO     connection established: ('127.0.0.1', 59812)
remi.server.ws   INFO     handshake complete
Wed Jan 24 15:07:00 2024 - SIGPIPE: writing to a closed pipe/socket/fd (probably the client disconnected) !!!
Wed Jan 24 15:07:00 2024 - uwsgi_response_write_body_do(): Broken pipe [core/writer.c line 429] during GET /video_feed (127.0.0.1)
OSError: write error
Exception ignored in: <function VideoCamera.__del__ at 0x7892435840>
Traceback (most recent call last):
  File "./camera.py", line 15, in __del__
    self.video.release()
AttributeError: 'cv3' object has no attribute 'release'
[pid: 8617|app: 0|req: 21/20] 127.0.0.1 () {48 vars in 1011 bytes} [Wed Jan 24 15:06:54 2024] GET /video_feed => generated 1883735 bytes in 5895 msecs (HTTP/1.0 200) 1 headers in 76 bytes (48 switches on core 0)
[pid: 8617|app: 0|req: 22/21] 127.0.0.1 () {42 vars in 735 bytes} [Wed Jan 24 15:07:02 2024] GET / => generated 146 bytes in 3 msecs (HTTP/1.0 200) 2 headers in 80 bytes (1 switches on core 0)
('app runs on port:', 39676)
Exception in thread Thread-6634:
Traceback (most recent call last):
  File "/usr/lib/python3.7/threading.py", line 917, in _bootstrap_inner
    self.run()
  File "/usr/lib/python3.7/threading.py", line 865, in run
    self._target(*self._args, **self._kwargs)
  File "cvs.py", line 184, in cvs.startcv
  File "/usr/local/lib/python3.7/dist-packages/remi/server.py", line 925, in start
    s = Server(main_gui_class, start=True, **kwargs)
  File "/usr/local/lib/python3.7/dist-packages/remi/server.py", line 816, in __init__
    self.start()
  File "/usr/local/lib/python3.7/dist-packages/remi/server.py", line 834, in start
    self, self._certfile, self._keyfile, self._ssl_version, *self._userdata)
  File "/usr/local/lib/python3.7/dist-packages/remi/server.py", line 762, in __init__
    HTTPServer.__init__(self, server_address, RequestHandlerClass)
  File "/usr/lib/python3.7/socketserver.py", line 452, in __init__
    self.server_bind()
  File "/usr/lib/python3.7/http/aid_server.py", line 138, in server_bind
    socketserver.TCPServer.server_bind(self)
  File "/usr/lib/python3.7/socketserver.py", line 466, in server_bind
    self.socket.bind(self.server_address)
OSError: [Errno 98] Address already in use

open the cam:1 ...
remi.server.ws   INFO     connection established: ('127.0.0.1', 59998)
remi.server.ws   INFO     handshake complete
*** Starting uWSGI 2.0.18-debian (64bit) on [Wed Jan 24 15:11:05 2024] ***
compiled with version: 8.2.0 on 10 February 2019 02:42:46
os: Linux-5.4.0-aidlite #1 SMP PREEMPT Thu Apr 21 03:06:08 CST 2022
nodename: localhost
machine: aarch64
clock source: unix
pcre jit disabled
detected number of CPU cores: 8
current working directory: /var/www/web
writing pidfile to uwsgi.pid
detected binary path: /usr/bin/uwsgi-core
uWSGI running as root, you can use --uid/--gid/--chroot options
*** WARNING: you are running uWSGI as root !!! (use the --uid flag) *** 
chdir() to /var/www/web
your processes number limit is 13584
your memory page size is 4096 bytes
detected max file descriptor number: 32768
lock engine: pthread robust mutexes
thunder lock: disabled (you can enable it with --thunder-lock)
uwsgi socket 0 bound to TCP address 127.0.0.1:1080 fd 3
uWSGI running as root, you can use --uid/--gid/--chroot options
*** WARNING: you are running uWSGI as root !!! (use the --uid flag) *** 
Python version: 3.7.3 (default, Oct 11 2023, 09:51:27)  [GCC 8.3.0]
Python main interpreter initialized at 0x30001194c0
uWSGI running as root, you can use --uid/--gid/--chroot options
*** WARNING: you are running uWSGI as root !!! (use the --uid flag) *** 
python threads support enabled
your server socket listen backlog is limited to 100 connections
your mercy for graceful operations on workers is 60 seconds
mapped 281440 bytes (274 KB) for 2 cores
*** Operational MODE: threaded ***
added /usr/bin/python to pythonpath.
WSGI app 0 (mountpoint='') ready in 6 seconds on interpreter 0x30001194c0 pid: 16524 (default app)
uWSGI running as root, you can use --uid/--gid/--chroot options
*** WARNING: you are running uWSGI as root !!! (use the --uid flag) *** 
*** uWSGI is running in multiple interpreter mode ***
spawned uWSGI master process (pid: 16524)
spawned uWSGI worker 1 (pid: 16548, cores: 2)
*** Stats server enabled on 127.0.0.1:5000 fd: 13 ***
[pid: 16548|app: 0|req: 1/1] 127.0.0.1 () {32 vars in 556 bytes} [Wed Jan 24 15:11:36 2024] GET / => generated 146 bytes in 71 msecs (HTTP/1.0 200) 2 headers in 80 bytes (1 switches on core 0)
signal only works in main thread
open the cam:1 ...
[pid: 16548|app: 0|req: 3/2] 127.0.0.1 () {42 vars in 735 bytes} [Wed Jan 24 15:12:34 2024] GET / => generated 146 bytes in 8 msecs (HTTP/1.0 200) 2 headers in 80 bytes (1 switches on core 0)
('app runs on port:', 52806)
open the cam:1 ...
remi.server      INFO     Started httpserver http://0.0.0.0:52806/
remi.request     INFO     built UI (path=/)
remi.server.ws   INFO     connection established: ('127.0.0.1', 35566)
remi.server.ws   INFO     handshake complete
Wed Jan 24 15:12:36 2024 - SIGPIPE: writing to a closed pipe/socket/fd (probably the client disconnected) !!!
remi.server.ws   ERROR    Error managing incoming websocket message
Traceback (most recent call last):
  File "/usr/local/lib/python3.7/dist-packages/remi/server.py", line 175, in read_next_message
    self.on_message(from_websocket(decoded))
  File "/usr/local/lib/python3.7/dist-packages/remi/server.py", line 245, in on_message
    self.send_message(_MSG_ACK)
  File "/usr/local/lib/python3.7/dist-packages/remi/server.py", line 209, in send_message
    self.request.sendall(out)
ConnectionResetError: [Errno 104] Connection reset by peer
remi.request     ERROR    sending websocket spontaneous message
Traceback (most recent call last):
  File "/usr/local/lib/python3.7/dist-packages/remi/server.py", line 497, in _send_spontaneous_websocket_message
    if ws.send_message(message):
  File "/usr/local/lib/python3.7/dist-packages/remi/server.py", line 209, in send_message
    self.request.sendall(out)
BrokenPipeError: [Errno 32] Broken pipe
remi.server.ws   INFO     connection established: ('127.0.0.1', 35576)
remi.server.ws   INFO     handshake complete
Wed Jan 24 15:13:00 2024 - SIGPIPE: writing to a closed pipe/socket/fd (probably the client disconnected) !!!
Wed Jan 24 15:13:00 2024 - uwsgi_response_write_body_do(): Broken pipe [core/writer.c line 429] during GET /video_feed (127.0.0.1)
OSError: write error
Exception ignored in: <function VideoCamera.__del__ at 0x762c3d8840>
Traceback (most recent call last):
  File "./camera.py", line 15, in __del__
    self.video.release()
AttributeError: 'cv3' object has no attribute 'release'
[pid: 16548|app: 0|req: 4/3] 127.0.0.1 () {48 vars in 1011 bytes} [Wed Jan 24 15:12:34 2024] GET /video_feed => generated 9833594 bytes in 25304 msecs (HTTP/1.0 200) 1 headers in 76 bytes (256 switches on core 0)
[pid: 16548|app: 0|req: 5/4] 127.0.0.1 () {42 vars in 735 bytes} [Wed Jan 24 15:13:00 2024] GET / => generated 146 bytes in 10 msecs (HTTP/1.0 200) 2 headers in 80 bytes (1 switches on core 0)
('app runs on port:', 52806)
open the cam:1 ...
Exception in thread Thread-516:
Traceback (most recent call last):
  File "/usr/lib/python3.7/threading.py", line 917, in _bootstrap_inner
    self.run()
  File "/usr/lib/python3.7/threading.py", line 865, in run
    self._target(*self._args, **self._kwargs)
  File "cvs.py", line 184, in cvs.startcv
  File "/usr/local/lib/python3.7/dist-packages/remi/server.py", line 925, in start
    s = Server(main_gui_class, start=True, **kwargs)
  File "/usr/local/lib/python3.7/dist-packages/remi/server.py", line 816, in __init__
    self.start()
  File "/usr/local/lib/python3.7/dist-packages/remi/server.py", line 834, in start
    self, self._certfile, self._keyfile, self._ssl_version, *self._userdata)
  File "/usr/local/lib/python3.7/dist-packages/remi/server.py", line 762, in __init__
    HTTPServer.__init__(self, server_address, RequestHandlerClass)
  File "/usr/lib/python3.7/socketserver.py", line 452, in __init__
    self.server_bind()
  File "/usr/lib/python3.7/http/aid_server.py", line 138, in server_bind
    socketserver.TCPServer.server_bind(self)
  File "/usr/lib/python3.7/socketserver.py", line 466, in server_bind
    self.socket.bind(self.server_address)
OSError: [Errno 98] Address already in use

remi.server.ws   INFO     connection established: ('127.0.0.1', 36638)
remi.server.ws   INFO     handshake complete
remi.server.ws   ERROR    Error managing incoming websocket message
Traceback (most recent call last):
  File "/usr/local/lib/python3.7/dist-packages/remi/server.py", line 175, in read_next_message
    self.on_message(from_websocket(decoded))
  File "/usr/local/lib/python3.7/dist-packages/remi/server.py", line 245, in on_message
    self.send_message(_MSG_ACK)
  File "/usr/local/lib/python3.7/dist-packages/remi/server.py", line 209, in send_message
    self.request.sendall(out)
ConnectionResetError: [Errno 104] Connection reset by peer
remi.server.ws   WARNING  ignoring message 2          (handshake not done)
remi.server.ws   INFO     connection established: ('127.0.0.1', 36660)
remi.server.ws   INFO     handshake complete
Wed Jan 24 15:13:25 2024 - SIGPIPE: writing to a closed pipe/socket/fd (probably the client disconnected) !!!
remi.request     ERROR    sending websocket spontaneous message
Traceback (most recent call last):
  File "/usr/local/lib/python3.7/dist-packages/remi/server.py", line 497, in _send_spontaneous_websocket_message
    if ws.send_message(message):
  File "/usr/local/lib/python3.7/dist-packages/remi/server.py", line 209, in send_message
    self.request.sendall(out)
BrokenPipeError: [Errno 32] Broken pipe
remi.server.ws   ERROR    exception in WebSocketsHandler.close method
Traceback (most recent call last):
  File "/usr/local/lib/python3.7/dist-packages/remi/server.py", line 279, in close
    self.request.shutdown(socket.SHUT_RDWR)
OSError: [Errno 107] Transport endpoint is not connected
Wed Jan 24 15:13:25 2024 - SIGPIPE: writing to a closed pipe/socket/fd (probably the client disconnected) !!!
remi.server.ws   ERROR    Error managing incoming websocket message
Traceback (most recent call last):
  File "/usr/local/lib/python3.7/dist-packages/remi/server.py", line 175, in read_next_message
    self.on_message(from_websocket(decoded))
  File "/usr/local/lib/python3.7/dist-packages/remi/server.py", line 245, in on_message
    self.send_message(_MSG_ACK)
  File "/usr/local/lib/python3.7/dist-packages/remi/server.py", line 209, in send_message
    self.request.sendall(out)
BrokenPipeError: [Errno 32] Broken pipe
remi.server.ws   WARNING  ignoring message 2          (handshake not done)
Wed Jan 24 15:13:26 2024 - SIGPIPE: writing to a closed pipe/socket/fd (probably the client disconnected) !!!
remi.server.ws   ERROR    Error managing incoming websocket message
Traceback (most recent call last):
  File "/usr/local/lib/python3.7/dist-packages/remi/server.py", line 175, in read_next_message
    self.on_message(from_websocket(decoded))
  File "/usr/local/lib/python3.7/dist-packages/remi/server.py", line 245, in on_message
    self.send_message(_MSG_ACK)
  File "/usr/local/lib/python3.7/dist-packages/remi/server.py", line 209, in send_message
    self.request.sendall(out)
BrokenPipeError: [Errno 32] Broken pipe
*** Starting uWSGI 2.0.18-debian (64bit) on [Wed Jan 24 15:16:47 2024] ***
compiled with version: 8.2.0 on 10 February 2019 02:42:46
os: Linux-5.4.0-aidlite #1 SMP PREEMPT Thu Apr 21 03:06:08 CST 2022
nodename: localhost
machine: aarch64
clock source: unix
pcre jit disabled
detected number of CPU cores: 8
current working directory: /var/www/web
writing pidfile to uwsgi.pid
detected binary path: /usr/bin/uwsgi-core
uWSGI running as root, you can use --uid/--gid/--chroot options
*** WARNING: you are running uWSGI as root !!! (use the --uid flag) *** 
chdir() to /var/www/web
your processes number limit is 13584
your memory page size is 4096 bytes
detected max file descriptor number: 32768
lock engine: pthread robust mutexes
thunder lock: disabled (you can enable it with --thunder-lock)
uwsgi socket 0 bound to TCP address 127.0.0.1:1080 fd 3
uWSGI running as root, you can use --uid/--gid/--chroot options
*** WARNING: you are running uWSGI as root !!! (use the --uid flag) *** 
Python version: 3.7.3 (default, Oct 11 2023, 09:51:27)  [GCC 8.3.0]
Python main interpreter initialized at 0x30001194c0
uWSGI running as root, you can use --uid/--gid/--chroot options
*** WARNING: you are running uWSGI as root !!! (use the --uid flag) *** 
python threads support enabled
your server socket listen backlog is limited to 100 connections
your mercy for graceful operations on workers is 60 seconds
mapped 281440 bytes (274 KB) for 2 cores
*** Operational MODE: threaded ***
added /usr/bin/python to pythonpath.
WSGI app 0 (mountpoint='') ready in 6 seconds on interpreter 0x30001194c0 pid: 17956 (default app)
uWSGI running as root, you can use --uid/--gid/--chroot options
*** WARNING: you are running uWSGI as root !!! (use the --uid flag) *** 
*** uWSGI is running in multiple interpreter mode ***
spawned uWSGI master process (pid: 17956)
spawned uWSGI worker 1 (pid: 17979, cores: 2)
*** Stats server enabled on 127.0.0.1:5000 fd: 13 ***
[pid: 17979|app: 0|req: 1/1] 127.0.0.1 () {34 vars in 882 bytes} [Wed Jan 24 15:19:25 2024] GET / => generated 146 bytes in 52 msecs (HTTP/1.0 200) 2 headers in 80 bytes (1 switches on core 0)
signal only works in main thread
open the cam:1 ...
[pid: 17979|app: 0|req: 3/2] 127.0.0.1 () {34 vars in 866 bytes} [Wed Jan 24 15:19:27 2024] GET /favicon.ico => generated 232 bytes in 4 msecs (HTTP/1.0 404) 2 headers in 87 bytes (1 switches on core 0)
[pid: 17979|app: 0|req: 4/3] 127.0.0.1 () {36 vars in 913 bytes} [Wed Jan 24 15:20:11 2024] GET / => generated 146 bytes in 14 msecs (HTTP/1.0 200) 2 headers in 80 bytes (1 switches on core 0)
Wed Jan 24 15:20:12 2024 - uwsgi_response_write_body_do(): Broken pipe [core/writer.c line 429] during GET /video_feed (127.0.0.1)
OSError: write error
Exception ignored in: <function VideoCamera.__del__ at 0x7069e7f840>
Traceback (most recent call last):
  File "./camera.py", line 15, in __del__
    self.video.release()
AttributeError: 'cv3' object has no attribute 'release'
[pid: 17979|app: 0|req: 4/4] 127.0.0.1 () {34 vars in 864 bytes} [Wed Jan 24 15:19:26 2024] GET /video_feed => generated 24592895 bytes in 45339 msecs (HTTP/1.0 200) 1 headers in 76 bytes (793 switches on core 1)
('app runs on port:', 12059)
remi.server      INFO     Started httpserver http://0.0.0.0:12059/
open the cam:1 ...
remi.request     INFO     built UI (path=/)
remi.server.ws   INFO     connection established: ('127.0.0.1', 34322)
remi.server.ws   INFO     handshake complete
Wed Jan 24 15:20:14 2024 - SIGPIPE: writing to a closed pipe/socket/fd (probably the client disconnected) !!!
Wed Jan 24 15:20:14 2024 - SIGPIPE: writing to a closed pipe/socket/fd (probably the client disconnected) !!!
remi.server.ws   ERROR    Error managing incoming websocket message
Traceback (most recent call last):
  File "/usr/local/lib/python3.7/dist-packages/remi/server.py", line 175, in read_next_message
    self.on_message(from_websocket(decoded))
  File "/usr/local/lib/python3.7/dist-packages/remi/server.py", line 245, in on_message
    self.send_message(_MSG_ACK)
  File "/usr/local/lib/python3.7/dist-packages/remi/server.py", line 209, in send_message
    self.request.sendall(out)
BrokenPipeError: [Errno 32] Broken pipe
remi.request     ERROR    sending websocket spontaneous message
Traceback (most recent call last):
  File "/usr/local/lib/python3.7/dist-packages/remi/server.py", line 497, in _send_spontaneous_websocket_message
    if ws.send_message(message):
  File "/usr/local/lib/python3.7/dist-packages/remi/server.py", line 209, in send_message
    self.request.sendall(out)
BrokenPipeError: [Errno 32] Broken pipe
remi.server.ws   INFO     connection established: ('127.0.0.1', 34334)
remi.server.ws   INFO     handshake complete
Wed Jan 24 15:20:23 2024 - SIGPIPE: writing to a closed pipe/socket/fd (probably the client disconnected) !!!
Wed Jan 24 15:20:23 2024 - SIGPIPE: writing to a closed pipe/socket/fd (probably the client disconnected) !!!
remi.server.ws   ERROR    Error managing incoming websocket message
Traceback (most recent call last):
  File "/usr/local/lib/python3.7/dist-packages/remi/server.py", line 175, in read_next_message
    self.on_message(from_websocket(decoded))
  File "/usr/local/lib/python3.7/dist-packages/remi/server.py", line 245, in on_message
    self.send_message(_MSG_ACK)
  File "/usr/local/lib/python3.7/dist-packages/remi/server.py", line 209, in send_message
    self.request.sendall(out)
BrokenPipeError: [Errno 32] Broken pipe
remi.request     ERROR    sending websocket spontaneous message
Traceback (most recent call last):
  File "/usr/local/lib/python3.7/dist-packages/remi/server.py", line 497, in _send_spontaneous_websocket_message
    if ws.send_message(message):
  File "/usr/local/lib/python3.7/dist-packages/remi/server.py", line 209, in send_message
    self.request.sendall(out)
BrokenPipeError: [Errno 32] Broken pipe
packet queue is empty, aborting
[pid: 17979|app: 0|req: 6/5] 127.0.0.1 () {32 vars in 576 bytes} [Wed Jan 24 15:24:57 2024] GET / => generated 146 bytes in 16 msecs (HTTP/1.0 200) 2 headers in 80 bytes (1 switches on core 1)
signal only works in main thread
open the cam:1 ...
Wed Jan 24 15:24:58 2024 - SIGPIPE: writing to a closed pipe/socket/fd (probably the client disconnected) !!!
Wed Jan 24 15:24:58 2024 - uwsgi_response_write_body_do(): Broken pipe [core/writer.c line 429] during GET /video_feed (127.0.0.1)
OSError: write error
Exception ignored in: <function VideoCamera.__del__ at 0x7069e7f840>
Traceback (most recent call last):
  File "./camera.py", line 15, in __del__
    self.video.release()
AttributeError: 'cv3' object has no attribute 'release'
[pid: 17979|app: 0|req: 7/6] 127.0.0.1 () {34 vars in 864 bytes} [Wed Jan 24 15:20:12 2024] GET /video_feed => generated 4494996 bytes in 285463 msecs (HTTP/1.0 200) 1 headers in 76 bytes (155 switches on core 0)
remi.server.ws   INFO     connection established: ('127.0.0.1', 34860)
remi.server.ws   INFO     handshake complete
Wed Jan 24 15:24:59 2024 - SIGPIPE: writing to a closed pipe/socket/fd (probably the client disconnected) !!!
remi.server.ws   ERROR    Error managing incoming websocket message
Traceback (most recent call last):
  File "/usr/local/lib/python3.7/dist-packages/remi/server.py", line 175, in read_next_message
    self.on_message(from_websocket(decoded))
  File "/usr/local/lib/python3.7/dist-packages/remi/server.py", line 245, in on_message
    self.send_message(_MSG_ACK)
  File "/usr/local/lib/python3.7/dist-packages/remi/server.py", line 209, in send_message
    self.request.sendall(out)
BrokenPipeError: [Errno 32] Broken pipe
remi.server.ws   INFO     connection established: ('127.0.0.1', 34870)
remi.server.ws   INFO     handshake complete
Corrupt JPEG data: bad Huffman code
Wed Jan 24 15:25:24 2024 - uwsgi_response_write_body_do(): Broken pipe [core/writer.c line 429] during GET /video_feed (127.0.0.1)
OSError: write error
Exception ignored in: <function VideoCamera.__del__ at 0x7069e7f840>
Traceback (most recent call last):
  File "./camera.py", line 15, in __del__
    self.video.release()
AttributeError: 'cv3' object has no attribute 'release'
[pid: 17979|app: 0|req: 7/7] 127.0.0.1 () {32 vars in 690 bytes} [Wed Jan 24 15:24:57 2024] GET /video_feed => generated 14741275 bytes in 26404 msecs (HTTP/1.0 200) 1 headers in 76 bytes (404 switches on core 1)
('app runs on port:', 12059)
open the cam:1 ...
Exception in thread Thread-178083:
Traceback (most recent call last):
  File "/usr/lib/python3.7/threading.py", line 917, in _bootstrap_inner
    self.run()
  File "/usr/lib/python3.7/threading.py", line 865, in run
    self._target(*self._args, **self._kwargs)
  File "cvs.py", line 184, in cvs.startcv
  File "/usr/local/lib/python3.7/dist-packages/remi/server.py", line 925, in start
    s = Server(main_gui_class, start=True, **kwargs)
  File "/usr/local/lib/python3.7/dist-packages/remi/server.py", line 816, in __init__
    self.start()
  File "/usr/local/lib/python3.7/dist-packages/remi/server.py", line 834, in start
    self, self._certfile, self._keyfile, self._ssl_version, *self._userdata)
  File "/usr/local/lib/python3.7/dist-packages/remi/server.py", line 762, in __init__
    HTTPServer.__init__(self, server_address, RequestHandlerClass)
  File "/usr/lib/python3.7/socketserver.py", line 452, in __init__
    self.server_bind()
  File "/usr/lib/python3.7/http/aid_server.py", line 138, in server_bind
    socketserver.TCPServer.server_bind(self)
  File "/usr/lib/python3.7/socketserver.py", line 466, in server_bind
    self.socket.bind(self.server_address)
OSError: [Errno 98] Address already in use

remi.server.ws   INFO     connection established: ('127.0.0.1', 53086)
remi.server.ws   INFO     handshake complete
Wed Jan 24 16:59:19 2024 - SIGPIPE: writing to a closed pipe/socket/fd (probably the client disconnected) !!!
remi.request     ERROR    sending websocket spontaneous message
Traceback (most recent call last):
  File "/usr/local/lib/python3.7/dist-packages/remi/server.py", line 497, in _send_spontaneous_websocket_message
    if ws.send_message(message):
  File "/usr/local/lib/python3.7/dist-packages/remi/server.py", line 209, in send_message
    self.request.sendall(out)
BrokenPipeError: [Errno 32] Broken pipe
remi.server.ws   ERROR    exception in WebSocketsHandler.close method
Traceback (most recent call last):
  File "/usr/local/lib/python3.7/dist-packages/remi/server.py", line 279, in close
    self.request.shutdown(socket.SHUT_RDWR)
OSError: [Errno 107] Transport endpoint is not connected
Wed Jan 24 16:59:19 2024 - SIGPIPE: writing to a closed pipe/socket/fd (probably the client disconnected) !!!
remi.server.ws   ERROR    Error managing incoming websocket message
Traceback (most recent call last):
  File "/usr/local/lib/python3.7/dist-packages/remi/server.py", line 175, in read_next_message
    self.on_message(from_websocket(decoded))
  File "/usr/local/lib/python3.7/dist-packages/remi/server.py", line 245, in on_message
    self.send_message(_MSG_ACK)
  File "/usr/local/lib/python3.7/dist-packages/remi/server.py", line 209, in send_message
    self.request.sendall(out)
BrokenPipeError: [Errno 32] Broken pipe
remi.server.ws   INFO     connection established: ('127.0.0.1', 53110)
remi.server.ws   INFO     handshake complete
Wed Jan 24 16:59:24 2024 - SIGPIPE: writing to a closed pipe/socket/fd (probably the client disconnected) !!!
Wed Jan 24 16:59:24 2024 - uwsgi_response_write_body_do(): Broken pipe [core/writer.c line 429] during GET /video_feed (127.0.0.1)
OSError: write error
Exception ignored in: <function VideoCamera.__del__ at 0x7069e7f840>
Traceback (most recent call last):
  File "./camera.py", line 15, in __del__
    self.video.release()
AttributeError: 'cv3' object has no attribute 'release'
[pid: 17979|app: 0|req: 8/8] 127.0.0.1 () {32 vars in 690 bytes} [Wed Jan 24 16:59:17 2024] GET /video_feed => generated 475716 bytes in 7057 msecs (HTTP/1.0 200) 1 headers in 76 bytes (87 switches on core 0)
*** Starting uWSGI 2.0.18-debian (64bit) on [Fri Jan 26 13:56:43 2024] ***
compiled with version: 8.2.0 on 10 February 2019 02:42:46
os: Linux-5.4.0-aidlite #1 SMP PREEMPT Thu Apr 21 03:06:08 CST 2022
nodename: localhost
machine: aarch64
clock source: unix
pcre jit disabled
detected number of CPU cores: 8
current working directory: /var/nginx_www
writing pidfile to uwsgi.pid
detected binary path: /usr/bin/uwsgi-core
uWSGI running as root, you can use --uid/--gid/--chroot options
*** WARNING: you are running uWSGI as root !!! (use the --uid flag) *** 
chdir() to /var/nginx_www/
your processes number limit is 13584
your memory page size is 4096 bytes
detected max file descriptor number: 32768
lock engine: pthread robust mutexes
thunder lock: disabled (you can enable it with --thunder-lock)
uwsgi socket 0 bound to TCP address 127.0.0.1:1080 fd 3
uWSGI running as root, you can use --uid/--gid/--chroot options
*** WARNING: you are running uWSGI as root !!! (use the --uid flag) *** 
Python version: 3.7.3 (default, Oct 11 2023, 09:51:27)  [GCC 8.3.0]
Python main interpreter initialized at 0x30001194c0
uWSGI running as root, you can use --uid/--gid/--chroot options
*** WARNING: you are running uWSGI as root !!! (use the --uid flag) *** 
python threads support enabled
your server socket listen backlog is limited to 100 connections
your mercy for graceful operations on workers is 60 seconds
mapped 281440 bytes (274 KB) for 2 cores
*** Operational MODE: threaded ***
added /usr/bin/python to pythonpath.
WSGI app 0 (mountpoint='') ready in 8 seconds on interpreter 0x30001194c0 pid: 29063 (default app)
uWSGI running as root, you can use --uid/--gid/--chroot options
*** WARNING: you are running uWSGI as root !!! (use the --uid flag) *** 
*** uWSGI is running in multiple interpreter mode ***
spawned uWSGI master process (pid: 29063)
spawned uWSGI worker 1 (pid: 29089, cores: 2)
*** Stats server enabled on 127.0.0.1:5000 fd: 13 ***
[pid: 29089|app: 0|req: 1/1] 127.0.0.1 () {34 vars in 719 bytes} [Fri Jan 26 13:58:16 2024] GET / => generated 146 bytes in 67 msecs (HTTP/1.0 200) 2 headers in 80 bytes (1 switches on core 0)
signal only works in main thread
open the cam:1 ...
[pid: 29089|app: 0|req: 3/2] 127.0.0.1 () {34 vars in 677 bytes} [Fri Jan 26 13:58:19 2024] GET /favicon.ico => generated 232 bytes in 16 msecs (HTTP/1.0 404) 2 headers in 87 bytes (1 switches on core 0)
Fri Jan 26 13:58:23 2024 - uwsgi_response_write_body_do(): Broken pipe [core/writer.c line 429] during GET /video_feed (127.0.0.1)
OSError: write error
Exception ignored in: <function VideoCamera.__del__ at 0x77bc88b840>
Traceback (most recent call last):
  File "./camera.py", line 15, in __del__
    self.video.release()
AttributeError: 'cv3' object has no attribute 'release'
[pid: 29089|app: 0|req: 3/3] 127.0.0.1 () {34 vars in 675 bytes} [Fri Jan 26 13:58:16 2024] GET /video_feed => generated 6784232 bytes in 6604 msecs (HTTP/1.0 200) 1 headers in 76 bytes (89 switches on core 1)
packet queue is empty, aborting
*** Starting uWSGI 2.0.18-debian (64bit) on [Sun Jan 28 03:24:51 2024] ***
compiled with version: 8.2.0 on 10 February 2019 02:42:46
os: Linux-5.4.0-aidlite #1 SMP PREEMPT Thu Apr 21 03:06:08 CST 2022
nodename: localhost
machine: aarch64
clock source: unix
pcre jit disabled
detected number of CPU cores: 8
current working directory: /var/nginx_www
writing pidfile to uwsgi.pid
detected binary path: /usr/bin/uwsgi-core
uWSGI running as root, you can use --uid/--gid/--chroot options
*** WARNING: you are running uWSGI as root !!! (use the --uid flag) *** 
chdir() to /var/nginx_www/
your processes number limit is 13584
your memory page size is 4096 bytes
detected max file descriptor number: 32768
lock engine: pthread robust mutexes
thunder lock: disabled (you can enable it with --thunder-lock)
uwsgi socket 0 bound to TCP address 127.0.0.1:1080 fd 3
uWSGI running as root, you can use --uid/--gid/--chroot options
*** WARNING: you are running uWSGI as root !!! (use the --uid flag) *** 
Python version: 3.7.3 (default, Oct 11 2023, 09:51:27)  [GCC 8.3.0]
Python main interpreter initialized at 0x300011aa40
uWSGI running as root, you can use --uid/--gid/--chroot options
*** WARNING: you are running uWSGI as root !!! (use the --uid flag) *** 
python threads support enabled
your server socket listen backlog is limited to 100 connections
your mercy for graceful operations on workers is 60 seconds
mapped 281440 bytes (274 KB) for 2 cores
*** Operational MODE: threaded ***
added /usr/bin/python to pythonpath.
WSGI app 0 (mountpoint='') ready in 6 seconds on interpreter 0x300011aa40 pid: 5822 (default app)
uWSGI running as root, you can use --uid/--gid/--chroot options
*** WARNING: you are running uWSGI as root !!! (use the --uid flag) *** 
*** uWSGI is running in multiple interpreter mode ***
spawned uWSGI master process (pid: 5822)
spawned uWSGI worker 1 (pid: 5849, cores: 2)
*** Stats server enabled on 127.0.0.1:5000 fd: 13 ***
[pid: 5849|app: 0|req: 1/1] 127.0.0.1 () {32 vars in 722 bytes} [Sun Jan 28 03:26:18 2024] GET / => generated 146 bytes in 69 msecs (HTTP/1.0 200) 2 headers in 80 bytes (1 switches on core 0)
signal only works in main thread
open the cam:1 ...
[pid: 5849|app: 0|req: 3/2] 127.0.0.1 () {32 vars in 705 bytes} [Sun Jan 28 03:26:20 2024] GET /favicon.ico => generated 232 bytes in 5 msecs (HTTP/1.0 404) 2 headers in 87 bytes (1 switches on core 0)
